2024-03-24 15:08:06,146 - INFO - httpx - HTTP Request: POST https://api.telegram.org/bot6841553936:AAFDcvQDqwLUUjPzfBKecIiV4LCKUfg14aY/getMe "HTTP/1.1 200 OK"
2024-03-24 15:08:06,693 - INFO - httpx - HTTP Request: POST https://api.telegram.org/bot6841553936:AAFDcvQDqwLUUjPzfBKecIiV4LCKUfg14aY/sendPhoto "HTTP/1.1 400 Bad Request"
2024-03-24 15:08:06,708 - WARNING - Mikobot - [ERROR] - Bot isn't able to send a message to the support_chat!
2024-03-24 15:08:57,645 - INFO - httpx - HTTP Request: POST https://api.telegram.org/bot6841553936:AAFDcvQDqwLUUjPzfBKecIiV4LCKUfg14aY/getMe "HTTP/1.1 200 OK"
2024-03-24 15:08:59,974 - INFO - httpx - HTTP Request: POST https://api.telegram.org/bot6841553936:AAFDcvQDqwLUUjPzfBKecIiV4LCKUfg14aY/sendPhoto "HTTP/1.1 400 Bad Request"
2024-03-24 15:08:59,974 - WARNING - Mikobot - [ERROR] - Bot isn't able to send a message to the support_chat!
2024-03-24 15:09:43,351 - INFO - httpx - HTTP Request: POST https://api.telegram.org/bot6841553936:AAFDcvQDqwLUUjPzfBKecIiV4LCKUfg14aY/sendPhoto "HTTP/1.1 400 Bad Request"
2024-03-24 15:09:43,351 - WARNING - Mikobot - [ERROR] - Bot isn't able to send a message to the support_chat!
2024-03-24 15:09:43,382 - INFO - httpx - HTTP Request: POST https://api.telegram.org/bot6841553936:AAFDcvQDqwLUUjPzfBKecIiV4LCKUfg14aY/getMe "HTTP/1.1 200 OK"
2024-03-24 15:09:43,694 - ERROR - Mikobot - [PostgreSQL] Failed to connect due to No module named 'psycopg2'
Traceback (most recent call last):
  File "C:\Users\Arnav\Tg\Test bot\Database\sql\__init__.py", line 22, in <module>
    SESSION = start()
              ^^^^^^^
  File "C:\Users\Arnav\Tg\Test bot\Database\sql\__init__.py", line 13, in start
    engine = create_engine(DB_URI, client_encoding="utf8")
             ^^^^^^^^^^^^^^^^^^^^^^^^^^^^^^^^^^^^^^^^^^^^^
  File "<string>", line 2, in create_engine
  File "C:\Users\Arnav\AppData\Local\Packages\PythonSoftwareFoundation.Python.3.12_qbz5n2kfra8p0\LocalCache\local-packages\Python312\site-packages\sqlalchemy\util\deprecations.py", line 281, in warned
    return fn(*args, **kwargs)  # type: ignore[no-any-return]
           ^^^^^^^^^^^^^^^^^^^
  File "C:\Users\Arnav\AppData\Local\Packages\PythonSoftwareFoundation.Python.3.12_qbz5n2kfra8p0\LocalCache\local-packages\Python312\site-packages\sqlalchemy\engine\create.py", line 599, in create_engine
    dbapi = dbapi_meth(**dbapi_args)
            ^^^^^^^^^^^^^^^^^^^^^^^^
  File "C:\Users\Arnav\AppData\Local\Packages\PythonSoftwareFoundation.Python.3.12_qbz5n2kfra8p0\LocalCache\local-packages\Python312\site-packages\sqlalchemy\dialects\postgresql\psycopg2.py", line 690, in import_dbapi
    import psycopg2
ModuleNotFoundError: No module named 'psycopg2'
2024-03-24 15:10:24,201 - INFO - httpx - HTTP Request: POST https://api.telegram.org/bot6841553936:AAFDcvQDqwLUUjPzfBKecIiV4LCKUfg14aY/getMe "HTTP/1.1 200 OK"
2024-03-24 15:10:25,037 - INFO - httpx - HTTP Request: POST https://api.telegram.org/bot6841553936:AAFDcvQDqwLUUjPzfBKecIiV4LCKUfg14aY/sendPhoto "HTTP/1.1 400 Bad Request"
2024-03-24 15:10:25,037 - WARNING - Mikobot - [ERROR] - Bot isn't able to send a message to the support_chat!
2024-03-24 15:10:25,435 - INFO - Mikobot - [PostgreSQL] Connecting to database......
2024-03-24 15:10:25,707 - ERROR - Mikobot - [PostgreSQL] Failed to connect due to (psycopg2.OperationalError) could not translate host name "karma.db.elephantsql.com" to address: No such host is known. 

(Background on this error at: https://sqlalche.me/e/20/e3q8)
Traceback (most recent call last):
  File "C:\Users\Arnav\AppData\Local\Packages\PythonSoftwareFoundation.Python.3.12_qbz5n2kfra8p0\LocalCache\local-packages\Python312\site-packages\sqlalchemy\engine\base.py", line 146, in __init__
    self._dbapi_connection = engine.raw_connection()
                             ^^^^^^^^^^^^^^^^^^^^^^^
  File "C:\Users\Arnav\AppData\Local\Packages\PythonSoftwareFoundation.Python.3.12_qbz5n2kfra8p0\LocalCache\local-packages\Python312\site-packages\sqlalchemy\engine\base.py", line 3304, in raw_connection
    return self.pool.connect()
           ^^^^^^^^^^^^^^^^^^^
  File "C:\Users\Arnav\AppData\Local\Packages\PythonSoftwareFoundation.Python.3.12_qbz5n2kfra8p0\LocalCache\local-packages\Python312\site-packages\sqlalchemy\pool\base.py", line 449, in connect
    return _ConnectionFairy._checkout(self)
           ^^^^^^^^^^^^^^^^^^^^^^^^^^^^^^^^
  File "C:\Users\Arnav\AppData\Local\Packages\PythonSoftwareFoundation.Python.3.12_qbz5n2kfra8p0\LocalCache\local-packages\Python312\site-packages\sqlalchemy\pool\base.py", line 1263, in _checkout
    fairy = _ConnectionRecord.checkout(pool)
            ^^^^^^^^^^^^^^^^^^^^^^^^^^^^^^^^
  File "C:\Users\Arnav\AppData\Local\Packages\PythonSoftwareFoundation.Python.3.12_qbz5n2kfra8p0\LocalCache\local-packages\Python312\site-packages\sqlalchemy\pool\base.py", line 712, in checkout
    rec = pool._do_get()
          ^^^^^^^^^^^^^^
  File "C:\Users\Arnav\AppData\Local\Packages\PythonSoftwareFoundation.Python.3.12_qbz5n2kfra8p0\LocalCache\local-packages\Python312\site-packages\sqlalchemy\pool\impl.py", line 179, in _do_get
    with util.safe_reraise():
  File "C:\Users\Arnav\AppData\Local\Packages\PythonSoftwareFoundation.Python.3.12_qbz5n2kfra8p0\LocalCache\local-packages\Python312\site-packages\sqlalchemy\util\langhelpers.py", line 146, in __exit__
    raise exc_value.with_traceback(exc_tb)
  File "C:\Users\Arnav\AppData\Local\Packages\PythonSoftwareFoundation.Python.3.12_qbz5n2kfra8p0\LocalCache\local-packages\Python312\site-packages\sqlalchemy\pool\impl.py", line 177, in _do_get
    return self._create_connection()
           ^^^^^^^^^^^^^^^^^^^^^^^^^
  File "C:\Users\Arnav\AppData\Local\Packages\PythonSoftwareFoundation.Python.3.12_qbz5n2kfra8p0\LocalCache\local-packages\Python312\site-packages\sqlalchemy\pool\base.py", line 390, in _create_connection
    return _ConnectionRecord(self)
           ^^^^^^^^^^^^^^^^^^^^^^^
  File "C:\Users\Arnav\AppData\Local\Packages\PythonSoftwareFoundation.Python.3.12_qbz5n2kfra8p0\LocalCache\local-packages\Python312\site-packages\sqlalchemy\pool\base.py", line 674, in __init__
    self.__connect()
  File "C:\Users\Arnav\AppData\Local\Packages\PythonSoftwareFoundation.Python.3.12_qbz5n2kfra8p0\LocalCache\local-packages\Python312\site-packages\sqlalchemy\pool\base.py", line 900, in __connect
    with util.safe_reraise():
  File "C:\Users\Arnav\AppData\Local\Packages\PythonSoftwareFoundation.Python.3.12_qbz5n2kfra8p0\LocalCache\local-packages\Python312\site-packages\sqlalchemy\util\langhelpers.py", line 146, in __exit__
    raise exc_value.with_traceback(exc_tb)
  File "C:\Users\Arnav\AppData\Local\Packages\PythonSoftwareFoundation.Python.3.12_qbz5n2kfra8p0\LocalCache\local-packages\Python312\site-packages\sqlalchemy\pool\base.py", line 896, in __connect
    self.dbapi_connection = connection = pool._invoke_creator(self)
                                         ^^^^^^^^^^^^^^^^^^^^^^^^^^
  File "C:\Users\Arnav\AppData\Local\Packages\PythonSoftwareFoundation.Python.3.12_qbz5n2kfra8p0\LocalCache\local-packages\Python312\site-packages\sqlalchemy\engine\create.py", line 643, in connect
    return dialect.connect(*cargs, **cparams)
           ^^^^^^^^^^^^^^^^^^^^^^^^^^^^^^^^^^
  File "C:\Users\Arnav\AppData\Local\Packages\PythonSoftwareFoundation.Python.3.12_qbz5n2kfra8p0\LocalCache\local-packages\Python312\site-packages\sqlalchemy\engine\default.py", line 617, in connect
    return self.loaded_dbapi.connect(*cargs, **cparams)
           ^^^^^^^^^^^^^^^^^^^^^^^^^^^^^^^^^^^^^^^^^^^^
  File "C:\Users\Arnav\AppData\Local\Packages\PythonSoftwareFoundation.Python.3.12_qbz5n2kfra8p0\LocalCache\local-packages\Python312\site-packages\psycopg2\__init__.py", line 122, in connect
    conn = _connect(dsn, connection_factory=connection_factory, **kwasync)
           ^^^^^^^^^^^^^^^^^^^^^^^^^^^^^^^^^^^^^^^^^^^^^^^^^^^^^^^^^^^^^^^
psycopg2.OperationalError: could not translate host name "karma.db.elephantsql.com" to address: No such host is known. 


The above exception was the direct cause of the following exception:

Traceback (most recent call last):
  File "C:\Users\Arnav\Tg\Test bot\Database\sql\__init__.py", line 22, in <module>
    SESSION = start()
              ^^^^^^^
  File "C:\Users\Arnav\Tg\Test bot\Database\sql\__init__.py", line 16, in start
    BASE.metadata.create_all(engine)
  File "C:\Users\Arnav\AppData\Local\Packages\PythonSoftwareFoundation.Python.3.12_qbz5n2kfra8p0\LocalCache\local-packages\Python312\site-packages\sqlalchemy\sql\schema.py", line 5825, in create_all
    bind._run_ddl_visitor(
  File "C:\Users\Arnav\AppData\Local\Packages\PythonSoftwareFoundation.Python.3.12_qbz5n2kfra8p0\LocalCache\local-packages\Python312\site-packages\sqlalchemy\engine\base.py", line 3254, in _run_ddl_visitor
    with self.begin() as conn:
  File "C:\Program Files\WindowsApps\PythonSoftwareFoundation.Python.3.12_3.12.752.0_x64__qbz5n2kfra8p0\Lib\contextlib.py", line 137, in __enter__
    return next(self.gen)
           ^^^^^^^^^^^^^^
  File "C:\Users\Arnav\AppData\Local\Packages\PythonSoftwareFoundation.Python.3.12_qbz5n2kfra8p0\LocalCache\local-packages\Python312\site-packages\sqlalchemy\engine\base.py", line 3244, in begin
    with self.connect() as conn:
         ^^^^^^^^^^^^^^
  File "C:\Users\Arnav\AppData\Local\Packages\PythonSoftwareFoundation.Python.3.12_qbz5n2kfra8p0\LocalCache\local-packages\Python312\site-packages\sqlalchemy\engine\base.py", line 3280, in connect
    return self._connection_cls(self)
           ^^^^^^^^^^^^^^^^^^^^^^^^^^
  File "C:\Users\Arnav\AppData\Local\Packages\PythonSoftwareFoundation.Python.3.12_qbz5n2kfra8p0\LocalCache\local-packages\Python312\site-packages\sqlalchemy\engine\base.py", line 148, in __init__
    Connection._handle_dbapi_exception_noconnection(
  File "C:\Users\Arnav\AppData\Local\Packages\PythonSoftwareFoundation.Python.3.12_qbz5n2kfra8p0\LocalCache\local-packages\Python312\site-packages\sqlalchemy\engine\base.py", line 2444, in _handle_dbapi_exception_noconnection
    raise sqlalchemy_exception.with_traceback(exc_info[2]) from e
  File "C:\Users\Arnav\AppData\Local\Packages\PythonSoftwareFoundation.Python.3.12_qbz5n2kfra8p0\LocalCache\local-packages\Python312\site-packages\sqlalchemy\engine\base.py", line 146, in __init__
    self._dbapi_connection = engine.raw_connection()
                             ^^^^^^^^^^^^^^^^^^^^^^^
  File "C:\Users\Arnav\AppData\Local\Packages\PythonSoftwareFoundation.Python.3.12_qbz5n2kfra8p0\LocalCache\local-packages\Python312\site-packages\sqlalchemy\engine\base.py", line 3304, in raw_connection
    return self.pool.connect()
           ^^^^^^^^^^^^^^^^^^^
  File "C:\Users\Arnav\AppData\Local\Packages\PythonSoftwareFoundation.Python.3.12_qbz5n2kfra8p0\LocalCache\local-packages\Python312\site-packages\sqlalchemy\pool\base.py", line 449, in connect
    return _ConnectionFairy._checkout(self)
           ^^^^^^^^^^^^^^^^^^^^^^^^^^^^^^^^
  File "C:\Users\Arnav\AppData\Local\Packages\PythonSoftwareFoundation.Python.3.12_qbz5n2kfra8p0\LocalCache\local-packages\Python312\site-packages\sqlalchemy\pool\base.py", line 1263, in _checkout
    fairy = _ConnectionRecord.checkout(pool)
            ^^^^^^^^^^^^^^^^^^^^^^^^^^^^^^^^
  File "C:\Users\Arnav\AppData\Local\Packages\PythonSoftwareFoundation.Python.3.12_qbz5n2kfra8p0\LocalCache\local-packages\Python312\site-packages\sqlalchemy\pool\base.py", line 712, in checkout
    rec = pool._do_get()
          ^^^^^^^^^^^^^^
  File "C:\Users\Arnav\AppData\Local\Packages\PythonSoftwareFoundation.Python.3.12_qbz5n2kfra8p0\LocalCache\local-packages\Python312\site-packages\sqlalchemy\pool\impl.py", line 179, in _do_get
    with util.safe_reraise():
  File "C:\Users\Arnav\AppData\Local\Packages\PythonSoftwareFoundation.Python.3.12_qbz5n2kfra8p0\LocalCache\local-packages\Python312\site-packages\sqlalchemy\util\langhelpers.py", line 146, in __exit__
    raise exc_value.with_traceback(exc_tb)
  File "C:\Users\Arnav\AppData\Local\Packages\PythonSoftwareFoundation.Python.3.12_qbz5n2kfra8p0\LocalCache\local-packages\Python312\site-packages\sqlalchemy\pool\impl.py", line 177, in _do_get
    return self._create_connection()
           ^^^^^^^^^^^^^^^^^^^^^^^^^
  File "C:\Users\Arnav\AppData\Local\Packages\PythonSoftwareFoundation.Python.3.12_qbz5n2kfra8p0\LocalCache\local-packages\Python312\site-packages\sqlalchemy\pool\base.py", line 390, in _create_connection
    return _ConnectionRecord(self)
           ^^^^^^^^^^^^^^^^^^^^^^^
  File "C:\Users\Arnav\AppData\Local\Packages\PythonSoftwareFoundation.Python.3.12_qbz5n2kfra8p0\LocalCache\local-packages\Python312\site-packages\sqlalchemy\pool\base.py", line 674, in __init__
    self.__connect()
  File "C:\Users\Arnav\AppData\Local\Packages\PythonSoftwareFoundation.Python.3.12_qbz5n2kfra8p0\LocalCache\local-packages\Python312\site-packages\sqlalchemy\pool\base.py", line 900, in __connect
    with util.safe_reraise():
  File "C:\Users\Arnav\AppData\Local\Packages\PythonSoftwareFoundation.Python.3.12_qbz5n2kfra8p0\LocalCache\local-packages\Python312\site-packages\sqlalchemy\util\langhelpers.py", line 146, in __exit__
    raise exc_value.with_traceback(exc_tb)
  File "C:\Users\Arnav\AppData\Local\Packages\PythonSoftwareFoundation.Python.3.12_qbz5n2kfra8p0\LocalCache\local-packages\Python312\site-packages\sqlalchemy\pool\base.py", line 896, in __connect
    self.dbapi_connection = connection = pool._invoke_creator(self)
                                         ^^^^^^^^^^^^^^^^^^^^^^^^^^
  File "C:\Users\Arnav\AppData\Local\Packages\PythonSoftwareFoundation.Python.3.12_qbz5n2kfra8p0\LocalCache\local-packages\Python312\site-packages\sqlalchemy\engine\create.py", line 643, in connect
    return dialect.connect(*cargs, **cparams)
           ^^^^^^^^^^^^^^^^^^^^^^^^^^^^^^^^^^
  File "C:\Users\Arnav\AppData\Local\Packages\PythonSoftwareFoundation.Python.3.12_qbz5n2kfra8p0\LocalCache\local-packages\Python312\site-packages\sqlalchemy\engine\default.py", line 617, in connect
    return self.loaded_dbapi.connect(*cargs, **cparams)
           ^^^^^^^^^^^^^^^^^^^^^^^^^^^^^^^^^^^^^^^^^^^^
  File "C:\Users\Arnav\AppData\Local\Packages\PythonSoftwareFoundation.Python.3.12_qbz5n2kfra8p0\LocalCache\local-packages\Python312\site-packages\psycopg2\__init__.py", line 122, in connect
    conn = _connect(dsn, connection_factory=connection_factory, **kwasync)
           ^^^^^^^^^^^^^^^^^^^^^^^^^^^^^^^^^^^^^^^^^^^^^^^^^^^^^^^^^^^^^^^
sqlalchemy.exc.OperationalError: (psycopg2.OperationalError) could not translate host name "karma.db.elephantsql.com" to address: No such host is known. 

(Background on this error at: https://sqlalche.me/e/20/e3q8)
2024-03-24 15:10:42,320 - INFO - httpx - HTTP Request: POST https://api.telegram.org/bot6841553936:AAFDcvQDqwLUUjPzfBKecIiV4LCKUfg14aY/sendPhoto "HTTP/1.1 400 Bad Request"
2024-03-24 15:10:42,320 - WARNING - Mikobot - [ERROR] - Bot isn't able to send a message to the support_chat!
2024-03-24 15:10:43,304 - INFO - httpx - HTTP Request: POST https://api.telegram.org/bot6841553936:AAFDcvQDqwLUUjPzfBKecIiV4LCKUfg14aY/getMe "HTTP/1.1 200 OK"
2024-03-24 15:10:43,632 - INFO - Mikobot - [PostgreSQL] Connecting to database......
2024-03-24 15:10:43,632 - ERROR - Mikobot - [PostgreSQL] Failed to connect due to (psycopg2.OperationalError) could not translate host name "karma.db.elephantsql.com" to address: No such host is known. 

(Background on this error at: https://sqlalche.me/e/20/e3q8)
Traceback (most recent call last):
  File "C:\Users\Arnav\AppData\Local\Packages\PythonSoftwareFoundation.Python.3.12_qbz5n2kfra8p0\LocalCache\local-packages\Python312\site-packages\sqlalchemy\engine\base.py", line 146, in __init__
    self._dbapi_connection = engine.raw_connection()
                             ^^^^^^^^^^^^^^^^^^^^^^^
  File "C:\Users\Arnav\AppData\Local\Packages\PythonSoftwareFoundation.Python.3.12_qbz5n2kfra8p0\LocalCache\local-packages\Python312\site-packages\sqlalchemy\engine\base.py", line 3304, in raw_connection
    return self.pool.connect()
           ^^^^^^^^^^^^^^^^^^^
  File "C:\Users\Arnav\AppData\Local\Packages\PythonSoftwareFoundation.Python.3.12_qbz5n2kfra8p0\LocalCache\local-packages\Python312\site-packages\sqlalchemy\pool\base.py", line 449, in connect
    return _ConnectionFairy._checkout(self)
           ^^^^^^^^^^^^^^^^^^^^^^^^^^^^^^^^
  File "C:\Users\Arnav\AppData\Local\Packages\PythonSoftwareFoundation.Python.3.12_qbz5n2kfra8p0\LocalCache\local-packages\Python312\site-packages\sqlalchemy\pool\base.py", line 1263, in _checkout
    fairy = _ConnectionRecord.checkout(pool)
            ^^^^^^^^^^^^^^^^^^^^^^^^^^^^^^^^
  File "C:\Users\Arnav\AppData\Local\Packages\PythonSoftwareFoundation.Python.3.12_qbz5n2kfra8p0\LocalCache\local-packages\Python312\site-packages\sqlalchemy\pool\base.py", line 712, in checkout
    rec = pool._do_get()
          ^^^^^^^^^^^^^^
  File "C:\Users\Arnav\AppData\Local\Packages\PythonSoftwareFoundation.Python.3.12_qbz5n2kfra8p0\LocalCache\local-packages\Python312\site-packages\sqlalchemy\pool\impl.py", line 179, in _do_get
    with util.safe_reraise():
  File "C:\Users\Arnav\AppData\Local\Packages\PythonSoftwareFoundation.Python.3.12_qbz5n2kfra8p0\LocalCache\local-packages\Python312\site-packages\sqlalchemy\util\langhelpers.py", line 146, in __exit__
    raise exc_value.with_traceback(exc_tb)
  File "C:\Users\Arnav\AppData\Local\Packages\PythonSoftwareFoundation.Python.3.12_qbz5n2kfra8p0\LocalCache\local-packages\Python312\site-packages\sqlalchemy\pool\impl.py", line 177, in _do_get
    return self._create_connection()
           ^^^^^^^^^^^^^^^^^^^^^^^^^
  File "C:\Users\Arnav\AppData\Local\Packages\PythonSoftwareFoundation.Python.3.12_qbz5n2kfra8p0\LocalCache\local-packages\Python312\site-packages\sqlalchemy\pool\base.py", line 390, in _create_connection
    return _ConnectionRecord(self)
           ^^^^^^^^^^^^^^^^^^^^^^^
  File "C:\Users\Arnav\AppData\Local\Packages\PythonSoftwareFoundation.Python.3.12_qbz5n2kfra8p0\LocalCache\local-packages\Python312\site-packages\sqlalchemy\pool\base.py", line 674, in __init__
    self.__connect()
  File "C:\Users\Arnav\AppData\Local\Packages\PythonSoftwareFoundation.Python.3.12_qbz5n2kfra8p0\LocalCache\local-packages\Python312\site-packages\sqlalchemy\pool\base.py", line 900, in __connect
    with util.safe_reraise():
  File "C:\Users\Arnav\AppData\Local\Packages\PythonSoftwareFoundation.Python.3.12_qbz5n2kfra8p0\LocalCache\local-packages\Python312\site-packages\sqlalchemy\util\langhelpers.py", line 146, in __exit__
    raise exc_value.with_traceback(exc_tb)
  File "C:\Users\Arnav\AppData\Local\Packages\PythonSoftwareFoundation.Python.3.12_qbz5n2kfra8p0\LocalCache\local-packages\Python312\site-packages\sqlalchemy\pool\base.py", line 896, in __connect
    self.dbapi_connection = connection = pool._invoke_creator(self)
                                         ^^^^^^^^^^^^^^^^^^^^^^^^^^
  File "C:\Users\Arnav\AppData\Local\Packages\PythonSoftwareFoundation.Python.3.12_qbz5n2kfra8p0\LocalCache\local-packages\Python312\site-packages\sqlalchemy\engine\create.py", line 643, in connect
    return dialect.connect(*cargs, **cparams)
           ^^^^^^^^^^^^^^^^^^^^^^^^^^^^^^^^^^
  File "C:\Users\Arnav\AppData\Local\Packages\PythonSoftwareFoundation.Python.3.12_qbz5n2kfra8p0\LocalCache\local-packages\Python312\site-packages\sqlalchemy\engine\default.py", line 617, in connect
    return self.loaded_dbapi.connect(*cargs, **cparams)
           ^^^^^^^^^^^^^^^^^^^^^^^^^^^^^^^^^^^^^^^^^^^^
  File "C:\Users\Arnav\AppData\Local\Packages\PythonSoftwareFoundation.Python.3.12_qbz5n2kfra8p0\LocalCache\local-packages\Python312\site-packages\psycopg2\__init__.py", line 122, in connect
    conn = _connect(dsn, connection_factory=connection_factory, **kwasync)
           ^^^^^^^^^^^^^^^^^^^^^^^^^^^^^^^^^^^^^^^^^^^^^^^^^^^^^^^^^^^^^^^
psycopg2.OperationalError: could not translate host name "karma.db.elephantsql.com" to address: No such host is known. 


The above exception was the direct cause of the following exception:

Traceback (most recent call last):
  File "C:\Users\Arnav\Tg\Test bot\Database\sql\__init__.py", line 22, in <module>
    SESSION = start()
              ^^^^^^^
  File "C:\Users\Arnav\Tg\Test bot\Database\sql\__init__.py", line 16, in start
    BASE.metadata.create_all(engine)
  File "C:\Users\Arnav\AppData\Local\Packages\PythonSoftwareFoundation.Python.3.12_qbz5n2kfra8p0\LocalCache\local-packages\Python312\site-packages\sqlalchemy\sql\schema.py", line 5825, in create_all
    bind._run_ddl_visitor(
  File "C:\Users\Arnav\AppData\Local\Packages\PythonSoftwareFoundation.Python.3.12_qbz5n2kfra8p0\LocalCache\local-packages\Python312\site-packages\sqlalchemy\engine\base.py", line 3254, in _run_ddl_visitor
    with self.begin() as conn:
  File "C:\Program Files\WindowsApps\PythonSoftwareFoundation.Python.3.12_3.12.752.0_x64__qbz5n2kfra8p0\Lib\contextlib.py", line 137, in __enter__
    return next(self.gen)
           ^^^^^^^^^^^^^^
  File "C:\Users\Arnav\AppData\Local\Packages\PythonSoftwareFoundation.Python.3.12_qbz5n2kfra8p0\LocalCache\local-packages\Python312\site-packages\sqlalchemy\engine\base.py", line 3244, in begin
    with self.connect() as conn:
         ^^^^^^^^^^^^^^
  File "C:\Users\Arnav\AppData\Local\Packages\PythonSoftwareFoundation.Python.3.12_qbz5n2kfra8p0\LocalCache\local-packages\Python312\site-packages\sqlalchemy\engine\base.py", line 3280, in connect
    return self._connection_cls(self)
           ^^^^^^^^^^^^^^^^^^^^^^^^^^
  File "C:\Users\Arnav\AppData\Local\Packages\PythonSoftwareFoundation.Python.3.12_qbz5n2kfra8p0\LocalCache\local-packages\Python312\site-packages\sqlalchemy\engine\base.py", line 148, in __init__
    Connection._handle_dbapi_exception_noconnection(
  File "C:\Users\Arnav\AppData\Local\Packages\PythonSoftwareFoundation.Python.3.12_qbz5n2kfra8p0\LocalCache\local-packages\Python312\site-packages\sqlalchemy\engine\base.py", line 2444, in _handle_dbapi_exception_noconnection
    raise sqlalchemy_exception.with_traceback(exc_info[2]) from e
  File "C:\Users\Arnav\AppData\Local\Packages\PythonSoftwareFoundation.Python.3.12_qbz5n2kfra8p0\LocalCache\local-packages\Python312\site-packages\sqlalchemy\engine\base.py", line 146, in __init__
    self._dbapi_connection = engine.raw_connection()
                             ^^^^^^^^^^^^^^^^^^^^^^^
  File "C:\Users\Arnav\AppData\Local\Packages\PythonSoftwareFoundation.Python.3.12_qbz5n2kfra8p0\LocalCache\local-packages\Python312\site-packages\sqlalchemy\engine\base.py", line 3304, in raw_connection
    return self.pool.connect()
           ^^^^^^^^^^^^^^^^^^^
  File "C:\Users\Arnav\AppData\Local\Packages\PythonSoftwareFoundation.Python.3.12_qbz5n2kfra8p0\LocalCache\local-packages\Python312\site-packages\sqlalchemy\pool\base.py", line 449, in connect
    return _ConnectionFairy._checkout(self)
           ^^^^^^^^^^^^^^^^^^^^^^^^^^^^^^^^
  File "C:\Users\Arnav\AppData\Local\Packages\PythonSoftwareFoundation.Python.3.12_qbz5n2kfra8p0\LocalCache\local-packages\Python312\site-packages\sqlalchemy\pool\base.py", line 1263, in _checkout
    fairy = _ConnectionRecord.checkout(pool)
            ^^^^^^^^^^^^^^^^^^^^^^^^^^^^^^^^
  File "C:\Users\Arnav\AppData\Local\Packages\PythonSoftwareFoundation.Python.3.12_qbz5n2kfra8p0\LocalCache\local-packages\Python312\site-packages\sqlalchemy\pool\base.py", line 712, in checkout
    rec = pool._do_get()
          ^^^^^^^^^^^^^^
  File "C:\Users\Arnav\AppData\Local\Packages\PythonSoftwareFoundation.Python.3.12_qbz5n2kfra8p0\LocalCache\local-packages\Python312\site-packages\sqlalchemy\pool\impl.py", line 179, in _do_get
    with util.safe_reraise():
  File "C:\Users\Arnav\AppData\Local\Packages\PythonSoftwareFoundation.Python.3.12_qbz5n2kfra8p0\LocalCache\local-packages\Python312\site-packages\sqlalchemy\util\langhelpers.py", line 146, in __exit__
    raise exc_value.with_traceback(exc_tb)
  File "C:\Users\Arnav\AppData\Local\Packages\PythonSoftwareFoundation.Python.3.12_qbz5n2kfra8p0\LocalCache\local-packages\Python312\site-packages\sqlalchemy\pool\impl.py", line 177, in _do_get
    return self._create_connection()
           ^^^^^^^^^^^^^^^^^^^^^^^^^
  File "C:\Users\Arnav\AppData\Local\Packages\PythonSoftwareFoundation.Python.3.12_qbz5n2kfra8p0\LocalCache\local-packages\Python312\site-packages\sqlalchemy\pool\base.py", line 390, in _create_connection
    return _ConnectionRecord(self)
           ^^^^^^^^^^^^^^^^^^^^^^^
  File "C:\Users\Arnav\AppData\Local\Packages\PythonSoftwareFoundation.Python.3.12_qbz5n2kfra8p0\LocalCache\local-packages\Python312\site-packages\sqlalchemy\pool\base.py", line 674, in __init__
    self.__connect()
  File "C:\Users\Arnav\AppData\Local\Packages\PythonSoftwareFoundation.Python.3.12_qbz5n2kfra8p0\LocalCache\local-packages\Python312\site-packages\sqlalchemy\pool\base.py", line 900, in __connect
    with util.safe_reraise():
  File "C:\Users\Arnav\AppData\Local\Packages\PythonSoftwareFoundation.Python.3.12_qbz5n2kfra8p0\LocalCache\local-packages\Python312\site-packages\sqlalchemy\util\langhelpers.py", line 146, in __exit__
    raise exc_value.with_traceback(exc_tb)
  File "C:\Users\Arnav\AppData\Local\Packages\PythonSoftwareFoundation.Python.3.12_qbz5n2kfra8p0\LocalCache\local-packages\Python312\site-packages\sqlalchemy\pool\base.py", line 896, in __connect
    self.dbapi_connection = connection = pool._invoke_creator(self)
                                         ^^^^^^^^^^^^^^^^^^^^^^^^^^
  File "C:\Users\Arnav\AppData\Local\Packages\PythonSoftwareFoundation.Python.3.12_qbz5n2kfra8p0\LocalCache\local-packages\Python312\site-packages\sqlalchemy\engine\create.py", line 643, in connect
    return dialect.connect(*cargs, **cparams)
           ^^^^^^^^^^^^^^^^^^^^^^^^^^^^^^^^^^
  File "C:\Users\Arnav\AppData\Local\Packages\PythonSoftwareFoundation.Python.3.12_qbz5n2kfra8p0\LocalCache\local-packages\Python312\site-packages\sqlalchemy\engine\default.py", line 617, in connect
    return self.loaded_dbapi.connect(*cargs, **cparams)
           ^^^^^^^^^^^^^^^^^^^^^^^^^^^^^^^^^^^^^^^^^^^^
  File "C:\Users\Arnav\AppData\Local\Packages\PythonSoftwareFoundation.Python.3.12_qbz5n2kfra8p0\LocalCache\local-packages\Python312\site-packages\psycopg2\__init__.py", line 122, in connect
    conn = _connect(dsn, connection_factory=connection_factory, **kwasync)
           ^^^^^^^^^^^^^^^^^^^^^^^^^^^^^^^^^^^^^^^^^^^^^^^^^^^^^^^^^^^^^^^
sqlalchemy.exc.OperationalError: (psycopg2.OperationalError) could not translate host name "karma.db.elephantsql.com" to address: No such host is known. 

(Background on this error at: https://sqlalche.me/e/20/e3q8)
2024-03-25 14:51:14,393 - INFO - httpx - HTTP Request: POST https://api.telegram.org/bot6841553936:AAFDcvQDqwLUUjPzfBKecIiV4LCKUfg14aY/getMe "HTTP/1.1 200 OK"
2024-03-25 14:51:14,576 - INFO - httpx - HTTP Request: POST https://api.telegram.org/bot6841553936:AAFDcvQDqwLUUjPzfBKecIiV4LCKUfg14aY/sendPhoto "HTTP/1.1 400 Bad Request"
2024-03-25 14:51:14,578 - WARNING - Mikobot - [ERROR] - Bot isn't able to send a message to the support_chat!
2024-03-25 14:51:15,045 - INFO - Mikobot - [PostgreSQL] Connecting to database......
2024-03-25 14:51:15,202 - ERROR - Mikobot - [PostgreSQL] Failed to connect due to (psycopg2.OperationalError) could not translate host name "karma.db.elephantsql.com" to address: No such host is known. 

(Background on this error at: https://sqlalche.me/e/20/e3q8)
Traceback (most recent call last):
  File "C:\Users\Arnav\AppData\Local\Packages\PythonSoftwareFoundation.Python.3.12_qbz5n2kfra8p0\LocalCache\local-packages\Python312\site-packages\sqlalchemy\engine\base.py", line 146, in __init__
    self._dbapi_connection = engine.raw_connection()
                             ^^^^^^^^^^^^^^^^^^^^^^^
  File "C:\Users\Arnav\AppData\Local\Packages\PythonSoftwareFoundation.Python.3.12_qbz5n2kfra8p0\LocalCache\local-packages\Python312\site-packages\sqlalchemy\engine\base.py", line 3304, in raw_connection
    return self.pool.connect()
           ^^^^^^^^^^^^^^^^^^^
  File "C:\Users\Arnav\AppData\Local\Packages\PythonSoftwareFoundation.Python.3.12_qbz5n2kfra8p0\LocalCache\local-packages\Python312\site-packages\sqlalchemy\pool\base.py", line 449, in connect
    return _ConnectionFairy._checkout(self)
           ^^^^^^^^^^^^^^^^^^^^^^^^^^^^^^^^
  File "C:\Users\Arnav\AppData\Local\Packages\PythonSoftwareFoundation.Python.3.12_qbz5n2kfra8p0\LocalCache\local-packages\Python312\site-packages\sqlalchemy\pool\base.py", line 1263, in _checkout
    fairy = _ConnectionRecord.checkout(pool)
            ^^^^^^^^^^^^^^^^^^^^^^^^^^^^^^^^
  File "C:\Users\Arnav\AppData\Local\Packages\PythonSoftwareFoundation.Python.3.12_qbz5n2kfra8p0\LocalCache\local-packages\Python312\site-packages\sqlalchemy\pool\base.py", line 712, in checkout
    rec = pool._do_get()
          ^^^^^^^^^^^^^^
  File "C:\Users\Arnav\AppData\Local\Packages\PythonSoftwareFoundation.Python.3.12_qbz5n2kfra8p0\LocalCache\local-packages\Python312\site-packages\sqlalchemy\pool\impl.py", line 179, in _do_get
    with util.safe_reraise():
  File "C:\Users\Arnav\AppData\Local\Packages\PythonSoftwareFoundation.Python.3.12_qbz5n2kfra8p0\LocalCache\local-packages\Python312\site-packages\sqlalchemy\util\langhelpers.py", line 146, in __exit__
    raise exc_value.with_traceback(exc_tb)
  File "C:\Users\Arnav\AppData\Local\Packages\PythonSoftwareFoundation.Python.3.12_qbz5n2kfra8p0\LocalCache\local-packages\Python312\site-packages\sqlalchemy\pool\impl.py", line 177, in _do_get
    return self._create_connection()
           ^^^^^^^^^^^^^^^^^^^^^^^^^
  File "C:\Users\Arnav\AppData\Local\Packages\PythonSoftwareFoundation.Python.3.12_qbz5n2kfra8p0\LocalCache\local-packages\Python312\site-packages\sqlalchemy\pool\base.py", line 390, in _create_connection
    return _ConnectionRecord(self)
           ^^^^^^^^^^^^^^^^^^^^^^^
  File "C:\Users\Arnav\AppData\Local\Packages\PythonSoftwareFoundation.Python.3.12_qbz5n2kfra8p0\LocalCache\local-packages\Python312\site-packages\sqlalchemy\pool\base.py", line 674, in __init__
    self.__connect()
  File "C:\Users\Arnav\AppData\Local\Packages\PythonSoftwareFoundation.Python.3.12_qbz5n2kfra8p0\LocalCache\local-packages\Python312\site-packages\sqlalchemy\pool\base.py", line 900, in __connect
    with util.safe_reraise():
  File "C:\Users\Arnav\AppData\Local\Packages\PythonSoftwareFoundation.Python.3.12_qbz5n2kfra8p0\LocalCache\local-packages\Python312\site-packages\sqlalchemy\util\langhelpers.py", line 146, in __exit__
    raise exc_value.with_traceback(exc_tb)
  File "C:\Users\Arnav\AppData\Local\Packages\PythonSoftwareFoundation.Python.3.12_qbz5n2kfra8p0\LocalCache\local-packages\Python312\site-packages\sqlalchemy\pool\base.py", line 896, in __connect
    self.dbapi_connection = connection = pool._invoke_creator(self)
                                         ^^^^^^^^^^^^^^^^^^^^^^^^^^
  File "C:\Users\Arnav\AppData\Local\Packages\PythonSoftwareFoundation.Python.3.12_qbz5n2kfra8p0\LocalCache\local-packages\Python312\site-packages\sqlalchemy\engine\create.py", line 643, in connect
    return dialect.connect(*cargs, **cparams)
           ^^^^^^^^^^^^^^^^^^^^^^^^^^^^^^^^^^
  File "C:\Users\Arnav\AppData\Local\Packages\PythonSoftwareFoundation.Python.3.12_qbz5n2kfra8p0\LocalCache\local-packages\Python312\site-packages\sqlalchemy\engine\default.py", line 617, in connect
    return self.loaded_dbapi.connect(*cargs, **cparams)
           ^^^^^^^^^^^^^^^^^^^^^^^^^^^^^^^^^^^^^^^^^^^^
  File "C:\Users\Arnav\AppData\Local\Packages\PythonSoftwareFoundation.Python.3.12_qbz5n2kfra8p0\LocalCache\local-packages\Python312\site-packages\psycopg2\__init__.py", line 122, in connect
    conn = _connect(dsn, connection_factory=connection_factory, **kwasync)
           ^^^^^^^^^^^^^^^^^^^^^^^^^^^^^^^^^^^^^^^^^^^^^^^^^^^^^^^^^^^^^^^
psycopg2.OperationalError: could not translate host name "karma.db.elephantsql.com" to address: No such host is known. 


The above exception was the direct cause of the following exception:

Traceback (most recent call last):
  File "C:\Users\Arnav\Tg\Test bot\Database\sql\__init__.py", line 22, in <module>
    SESSION = start()
              ^^^^^^^
  File "C:\Users\Arnav\Tg\Test bot\Database\sql\__init__.py", line 16, in start
    BASE.metadata.create_all(engine)
  File "C:\Users\Arnav\AppData\Local\Packages\PythonSoftwareFoundation.Python.3.12_qbz5n2kfra8p0\LocalCache\local-packages\Python312\site-packages\sqlalchemy\sql\schema.py", line 5825, in create_all
    bind._run_ddl_visitor(
  File "C:\Users\Arnav\AppData\Local\Packages\PythonSoftwareFoundation.Python.3.12_qbz5n2kfra8p0\LocalCache\local-packages\Python312\site-packages\sqlalchemy\engine\base.py", line 3254, in _run_ddl_visitor
    with self.begin() as conn:
  File "C:\Program Files\WindowsApps\PythonSoftwareFoundation.Python.3.12_3.12.752.0_x64__qbz5n2kfra8p0\Lib\contextlib.py", line 137, in __enter__
    return next(self.gen)
           ^^^^^^^^^^^^^^
  File "C:\Users\Arnav\AppData\Local\Packages\PythonSoftwareFoundation.Python.3.12_qbz5n2kfra8p0\LocalCache\local-packages\Python312\site-packages\sqlalchemy\engine\base.py", line 3244, in begin
    with self.connect() as conn:
         ^^^^^^^^^^^^^^
  File "C:\Users\Arnav\AppData\Local\Packages\PythonSoftwareFoundation.Python.3.12_qbz5n2kfra8p0\LocalCache\local-packages\Python312\site-packages\sqlalchemy\engine\base.py", line 3280, in connect
    return self._connection_cls(self)
           ^^^^^^^^^^^^^^^^^^^^^^^^^^
  File "C:\Users\Arnav\AppData\Local\Packages\PythonSoftwareFoundation.Python.3.12_qbz5n2kfra8p0\LocalCache\local-packages\Python312\site-packages\sqlalchemy\engine\base.py", line 148, in __init__
    Connection._handle_dbapi_exception_noconnection(
  File "C:\Users\Arnav\AppData\Local\Packages\PythonSoftwareFoundation.Python.3.12_qbz5n2kfra8p0\LocalCache\local-packages\Python312\site-packages\sqlalchemy\engine\base.py", line 2444, in _handle_dbapi_exception_noconnection
    raise sqlalchemy_exception.with_traceback(exc_info[2]) from e
  File "C:\Users\Arnav\AppData\Local\Packages\PythonSoftwareFoundation.Python.3.12_qbz5n2kfra8p0\LocalCache\local-packages\Python312\site-packages\sqlalchemy\engine\base.py", line 146, in __init__
    self._dbapi_connection = engine.raw_connection()
                             ^^^^^^^^^^^^^^^^^^^^^^^
  File "C:\Users\Arnav\AppData\Local\Packages\PythonSoftwareFoundation.Python.3.12_qbz5n2kfra8p0\LocalCache\local-packages\Python312\site-packages\sqlalchemy\engine\base.py", line 3304, in raw_connection
    return self.pool.connect()
           ^^^^^^^^^^^^^^^^^^^
  File "C:\Users\Arnav\AppData\Local\Packages\PythonSoftwareFoundation.Python.3.12_qbz5n2kfra8p0\LocalCache\local-packages\Python312\site-packages\sqlalchemy\pool\base.py", line 449, in connect
    return _ConnectionFairy._checkout(self)
           ^^^^^^^^^^^^^^^^^^^^^^^^^^^^^^^^
  File "C:\Users\Arnav\AppData\Local\Packages\PythonSoftwareFoundation.Python.3.12_qbz5n2kfra8p0\LocalCache\local-packages\Python312\site-packages\sqlalchemy\pool\base.py", line 1263, in _checkout
    fairy = _ConnectionRecord.checkout(pool)
            ^^^^^^^^^^^^^^^^^^^^^^^^^^^^^^^^
  File "C:\Users\Arnav\AppData\Local\Packages\PythonSoftwareFoundation.Python.3.12_qbz5n2kfra8p0\LocalCache\local-packages\Python312\site-packages\sqlalchemy\pool\base.py", line 712, in checkout
    rec = pool._do_get()
          ^^^^^^^^^^^^^^
  File "C:\Users\Arnav\AppData\Local\Packages\PythonSoftwareFoundation.Python.3.12_qbz5n2kfra8p0\LocalCache\local-packages\Python312\site-packages\sqlalchemy\pool\impl.py", line 179, in _do_get
    with util.safe_reraise():
  File "C:\Users\Arnav\AppData\Local\Packages\PythonSoftwareFoundation.Python.3.12_qbz5n2kfra8p0\LocalCache\local-packages\Python312\site-packages\sqlalchemy\util\langhelpers.py", line 146, in __exit__
    raise exc_value.with_traceback(exc_tb)
  File "C:\Users\Arnav\AppData\Local\Packages\PythonSoftwareFoundation.Python.3.12_qbz5n2kfra8p0\LocalCache\local-packages\Python312\site-packages\sqlalchemy\pool\impl.py", line 177, in _do_get
    return self._create_connection()
           ^^^^^^^^^^^^^^^^^^^^^^^^^
  File "C:\Users\Arnav\AppData\Local\Packages\PythonSoftwareFoundation.Python.3.12_qbz5n2kfra8p0\LocalCache\local-packages\Python312\site-packages\sqlalchemy\pool\base.py", line 390, in _create_connection
    return _ConnectionRecord(self)
           ^^^^^^^^^^^^^^^^^^^^^^^
  File "C:\Users\Arnav\AppData\Local\Packages\PythonSoftwareFoundation.Python.3.12_qbz5n2kfra8p0\LocalCache\local-packages\Python312\site-packages\sqlalchemy\pool\base.py", line 674, in __init__
    self.__connect()
  File "C:\Users\Arnav\AppData\Local\Packages\PythonSoftwareFoundation.Python.3.12_qbz5n2kfra8p0\LocalCache\local-packages\Python312\site-packages\sqlalchemy\pool\base.py", line 900, in __connect
    with util.safe_reraise():
  File "C:\Users\Arnav\AppData\Local\Packages\PythonSoftwareFoundation.Python.3.12_qbz5n2kfra8p0\LocalCache\local-packages\Python312\site-packages\sqlalchemy\util\langhelpers.py", line 146, in __exit__
    raise exc_value.with_traceback(exc_tb)
  File "C:\Users\Arnav\AppData\Local\Packages\PythonSoftwareFoundation.Python.3.12_qbz5n2kfra8p0\LocalCache\local-packages\Python312\site-packages\sqlalchemy\pool\base.py", line 896, in __connect
    self.dbapi_connection = connection = pool._invoke_creator(self)
                                         ^^^^^^^^^^^^^^^^^^^^^^^^^^
  File "C:\Users\Arnav\AppData\Local\Packages\PythonSoftwareFoundation.Python.3.12_qbz5n2kfra8p0\LocalCache\local-packages\Python312\site-packages\sqlalchemy\engine\create.py", line 643, in connect
    return dialect.connect(*cargs, **cparams)
           ^^^^^^^^^^^^^^^^^^^^^^^^^^^^^^^^^^
  File "C:\Users\Arnav\AppData\Local\Packages\PythonSoftwareFoundation.Python.3.12_qbz5n2kfra8p0\LocalCache\local-packages\Python312\site-packages\sqlalchemy\engine\default.py", line 617, in connect
    return self.loaded_dbapi.connect(*cargs, **cparams)
           ^^^^^^^^^^^^^^^^^^^^^^^^^^^^^^^^^^^^^^^^^^^^
  File "C:\Users\Arnav\AppData\Local\Packages\PythonSoftwareFoundation.Python.3.12_qbz5n2kfra8p0\LocalCache\local-packages\Python312\site-packages\psycopg2\__init__.py", line 122, in connect
    conn = _connect(dsn, connection_factory=connection_factory, **kwasync)
           ^^^^^^^^^^^^^^^^^^^^^^^^^^^^^^^^^^^^^^^^^^^^^^^^^^^^^^^^^^^^^^^
sqlalchemy.exc.OperationalError: (psycopg2.OperationalError) could not translate host name "karma.db.elephantsql.com" to address: No such host is known. 

(Background on this error at: https://sqlalche.me/e/20/e3q8)
2024-03-25 18:30:36,723 - INFO - httpx - HTTP Request: POST https://api.telegram.org/bot6841553936:AAFDcvQDqwLUUjPzfBKecIiV4LCKUfg14aY/sendPhoto "HTTP/1.1 400 Bad Request"
2024-03-25 18:30:36,723 - WARNING - Mikobot - [ERROR] - Bot isn't able to send a message to the support_chat!
2024-03-25 18:30:37,374 - INFO - httpx - HTTP Request: POST https://api.telegram.org/bot6841553936:AAFDcvQDqwLUUjPzfBKecIiV4LCKUfg14aY/getMe "HTTP/1.1 200 OK"
2024-03-25 18:30:37,938 - INFO - Mikobot - [PostgreSQL] Connecting to database......
2024-03-25 18:30:42,885 - INFO - Mikobot - [PostgreSQL] Connection successful, session started.
2024-03-25 18:31:45,633 - INFO - httpx - HTTP Request: POST https://api.telegram.org/bot6841553936:AAFDcvQDqwLUUjPzfBKecIiV4LCKUfg14aY/sendPhoto "HTTP/1.1 400 Bad Request"
2024-03-25 18:31:45,634 - WARNING - Mikobot - [ERROR] - Bot isn't able to send a message to the support_chat!
2024-03-25 18:31:45,652 - INFO - httpx - HTTP Request: POST https://api.telegram.org/bot6841553936:AAFDcvQDqwLUUjPzfBKecIiV4LCKUfg14aY/getMe "HTTP/1.1 200 OK"
2024-03-25 18:31:46,002 - INFO - Mikobot - [PostgreSQL] Connecting to database......
2024-03-25 18:31:50,815 - INFO - Mikobot - [PostgreSQL] Connection successful, session started.
2024-03-29 19:02:21,642 - INFO - httpx - HTTP Request: POST https://api.telegram.org/bot6841553936:AAFDcvQDqwLUUjPzfBKecIiV4LCKUfg14aY/getMe "HTTP/1.1 200 OK"
2024-03-29 19:02:21,678 - INFO - httpx - HTTP Request: POST https://api.telegram.org/bot6841553936:AAFDcvQDqwLUUjPzfBKecIiV4LCKUfg14aY/sendPhoto "HTTP/1.1 400 Bad Request"
2024-03-29 19:02:21,679 - WARNING - Mikobot - [ERROR] - Bot isn't able to send a message to the support_chat!
2024-03-29 19:02:22,164 - INFO - Mikobot - [PostgreSQL] Connecting to database......
2024-03-29 19:02:27,442 - INFO - Mikobot - [PostgreSQL] Connection successful, session started.
